Workbook

Sheet Emissions
A1: Model | B1: Scenario | C1: Region | D1: Variable | E1: Position | F1: Type | G1: Position2 | H1: Index | I1: Code | J1: Linestyle | K1: Delayed | L1: Color | M1: Baseline | N1: Unit | O1: 2015 | P1: 2020 | Q1: 2025 | R1: 2030 | S1: 2035 | T1: 2040 | U1: 2045 | V1: 2050 | W1: 2055 | X1: 2060 | Y1: 2065 | Z1: 2070 | AA1: 2075 | AB1: 2080 | AC1: 2085 | AD1: 2090 | AE1: 2095 | AF1: 2100
A2: GCAM2021 | B2: Current Policies | C2: World | D2: Emissions|CO2 | E2: 11 | F2: NT | G2: 35 | H2: 35 | I2: 1 | J2: solid | K2: 0 | L2: black | M2: 1 | N2: Mt CO2/yr | O2: 40.088074 | P2: =Feuil1!L6/1000 -> 41.748377 | Q2: =Feuil1!M6/1000 -> 42.870429 | R2: =Feuil1!N6/1000 -> 43.254566 | S2: =Feuil1!O6/1000 -> 44.092383 | T2: =Feuil1!P6/1000 -> 43.65493 | U2: =Feuil1!Q6/1000 -> 43.423747 | V2: =Feuil1!R6/1000 -> 42.993373 | W2: =Feuil1!S6/1000 -> 44.085214 | ... AF2: =Feuil1!AB6/1000 -> 47.172663
A3: MESSAGE2021 | B3: Current Policies | C3: World | D3: Emissions|CO2 | E3: 11 | F3: NT | G3: 35 | H3: 35 | I3: 1 | J3: dashed | K3: 0 | L3: black | M3: 1 | N3: Mt CO2/yr | O3: 43.281866 | P3: =Feuil1!L12/1000 -> 42.186671 | Q3: =Feuil1!M12/1000 -> 41.961094 | R3: =Feuil1!N12/1000 -> 43.923257 | S3: =Feuil1!O12/1000 -> 45.475716 | T3: =Feuil1!P12/1000 -> 46.165963 | U3: =Feuil1!Q12/1000 -> 47.455607 | V3: =Feuil1!R12/1000 -> 48.830181 | W3: =Feuil1!S12/1000 -> 50.403311 | X3: =Feuil1!T12/1000 -> 50.760493 | Z3: =Feuil1!V12/1000 -> 53.578041 | AB3: =Feuil1!X12/1000 -> 60.79401 | AD3: =Feuil1!Z12/1000 -> 65.799357 | AF3: =Feuil1!AB12/1000 -> 68.642039
A4: REMIND2021 | B4: Current Policies | C4: World | D4: Emissions|CO2 | E4: 11 | F4: NT | G4: 35 | H4: 35 | I4: 1 | J4: dotted | K4: 0 | L4: black | M4: 1 | N4: Mt CO2/yr | O4: 39.283613 | P4: =Feuil1!L18/1000 -> 39.860861 | Q4: =Feuil1!M18/1000 -> 41.286547 | R4: =Feuil1!N18/1000 -> 42.659504 | S4: =Feuil1!O18/1000 -> 43.132513 | T4: =Feuil1!P18/1000 -> 42.609539 | U4: =Feuil1!Q18/1000 -> 42.184799 | V4: =Feuil1!R18/1000 -> 41.927365 | W4: =Feuil1!S18/1000 -> 41.317866 | X4: =Feuil1!T18/1000 -> 40.75866 | Z4: =Feuil1!V18/1000 -> 39.453863 | AB4: =Feuil1!X18/1000 -> 38.015772 | AD4: =Feuil1!Z18/1000 -> 34.313074 | AF4: =Feuil1!AB18/1000 -> 30.117557
A5: GCAM2021 | B5: NDC | C5: World | D5: Emissions|CO2 | E5: 12 | F5: NT | G5: 35 | H5: 35 | I5: 2 | J5: solid | K5: 0 | L5: grey | M5: 0 | N5: Mt CO2/yr | O5: 40.088074 | P5: =Feuil1!L3/1000 -> 42.010319 | Q5: =Feuil1!M3/1000 -> 41.518275 | R5: =Feuil1!N3/1000 -> 39.157197 | S5: =Feuil1!O3/1000 -> 36.726453 | T5: =Feuil1!P3/1000 -> 34.248834 | U5: =Feuil1!Q3/1000 -> 31.693521 | V5: =Feuil1!R3/1000 -> 28.901923 | W5: =Feuil1!S3/1000 -> 27.006103 | ... AF5: =Feuil1!AB3/1000 -> 15.817734
A6: MESSAGE2021 | B6: NDC | C6: World | D6: Emissions|CO2 | E6: 12 | F6: NT | G6: 35 | H6: 35 | I6: 2 | J6: dashed | K6: 0 | L6: grey | M6: 0 | N6: Mt CO2/yr | O6: 43.281866 | P6: =Feuil1!L9/1000 -> 42.186671 | Q6: =Feuil1!M9/1000 -> 39.683069 | R6: =Feuil1!N9/1000 -> 39.561825 | S6: =Feuil1!O9/1000 -> 39.291989 | T6: =Feuil1!P9/1000 -> 36.99337 | U6: =Feuil1!Q9/1000 -> 35.315429 | V6: =Feuil1!R9/1000 -> 33.195025 | W6: =Feuil1!S9/1000 -> 31.281624 | X6: =Feuil1!T9/1000 -> 29.501521 | Z6: =Feuil1!V9/1000 -> 27.898152 | AB6: =Feuil1!X9/1000 -> 26.807177 | AD6: =Feuil1!Z9/1000 -> 22.933888 | AF6: =Feuil1!AB9/1000 -> 19.522563
A7: REMIND2021 | B7: NDC | C7: World | D7: Emissions|CO2 | E7: 12 | F7: NT | G7: 35 | H7: 35 | I7: 2 | J7: dotted | K7: 0 | L7: grey | M7: 0 | N7: Mt CO2/yr | O7: 39.283613 | P7: =Feuil1!L15/1000 -> 39.860861 | Q7: =Feuil1!M15/1000 -> 40.871447 | R7: =Feuil1!N15/1000 -> 40.720627 | S7: =Feuil1!O15/1000 -> 38.904909 | T7: =Feuil1!P15/1000 -> 34.834107 | U7: =Feuil1!Q15/1000 -> 30.650156 | V7: =Feuil1!R15/1000 -> 27.85762 | W7: =Feuil1!S15/1000 -> 25.455274 | X7: =Feuil1!T15/1000 -> 23.566903 | Z7: =Feuil1!V15/1000 -> 18.119073 | AB7: =Feuil1!X15/1000 -> 14.001371 | AD7: =Feuil1!Z15/1000 -> 10.084444 | AF7: =Feuil1!AB15/1000 -> 7.7211935
A8: GCAM2021 | B8: Below 2°C | C8: World | D8: Emissions|CO2 | E8: 13 | F8: Ord | G8: 35 | H8: 35 | I8: 3 | J8: solid | K8: 0 | L8: royalblue | M8: 0 | N8: Mt CO2/yr | O8: 40.088074 | P8: =Feuil1!L2/1000 -> 41.741753 | Q8: =Feuil1!M2/1000 -> 37.793758 | R8: =Feuil1!N2/1000 -> 32.406955 | S8: =Feuil1!O2/1000 -> 25.829202 | T8: =Feuil1!P2/1000 -> 18.922584 | U8: =Feuil1!Q2/1000 -> 12.067988 | V8: =Feuil1!R2/1000 -> 8.2784755 | W8: =Feuil1!S2/1000 -> 4.6456852 | ... AF8: =Feuil1!AB2/1000 -> -1.2476435
A9: MESSAGE2021 | B9: Below 2°C | C9: World | D9: Emissions|CO2 | E9: 13 | F9: Ord | G9: 35 | H9: 35 | I9: 3 | J9: dashed | K9: 0 | L9: royalblue | M9: 0 | N9: Mt CO2/yr | O9: 43.281866 | P9: =Feuil1!L8/1000 -> 42.186671 | Q9: =Feuil1!M8/1000 -> 33.099994 | R9: =Feuil1!N8/1000 -> 28.346452 | S9: =Feuil1!O8/1000 -> 25.099181 | T9: =Feuil1!P8/1000 -> 21.665792 | U9: =Feuil1!Q8/1000 -> 17.637859 | V9: =Feuil1!R8/1000 -> 13.326326 | W9: =Feuil1!S8/1000 -> 9.8319234 | X9: =Feuil1!T8/1000 -> 7.1207952 | Z9: =Feuil1!V8/1000 -> 2.4382968 | AB9: =Feuil1!X8/1000 -> 1.9765012e-06 | AD9: =Feuil1!Z8/1000 -> -2.7184535e-06 | AF9: =Feuil1!AB8/1000 -> 2.6274698e-08
A10: REMIND2021 | B10: Below 2°C | C10: World | D10: Emissions|CO2 | E10: 13 | F10: Ord | G10: 35 | H10: 35 | I10: 3 | J10: dotted | K10: 0 | L10: royalblue | M10: 0 | N10: Mt CO2/yr | O10: 39.283613 | P10: =Feuil1!L14/1000 -> 39.860861 | Q10: =Feuil1!M14/1000 -> 32.974091 | R10: =Feuil1!N14/1000 -> 28.023844 | S10: =Feuil1!O14/1000 -> 22.449621 | T10: =Feuil1!P14/1000 -> 16.923235 | U10: =Feuil1!Q14/1000 -> 12.75609 | V10: =Feuil1!R14/1000 -> 9.526017 | W10: =Feuil1!S14/1000 -> 6.9836848 | X10: =Feuil1!T14/1000 -> 5.109653 | Z10: =Feuil1!V14/1000 -> 2.6551331 | AB10: =Feuil1!X14/1000 -> 1.3720141 | AD10: =Feuil1!Z14/1000 -> 0.6739603 | AF10: =Feuil1!AB14/1000 -> 0.1209158
A11: GCAM2021 | B11: Net Zero 2050 | C11: World | D11: Emissions|CO2 | E11: 14 | F11: Ord | G11: 15 | H11: 15 | I11: 4 | J11: solid | K11: 0 | L11: limegreen | M11: 0 | N11: Mt CO2/yr | O11: 40.088074 | P11: =Feuil1!L7/1000 -> 41.747491 | Q11: =Feuil1!M7/1000 -> 34.422147 | R11: =Feuil1!N7/1000 -> 27.631832 | S11: =Feuil1!O7/1000 -> 18.783933 | T11: =Feuil1!P7/1000 -> 10.015229 | U11: =Feuil1!Q7/1000 -> 4.7477467 | V11: =Feuil1!R7/1000 -> -0.31104255 | W11: =Feuil1!S7/1000 -> -3.2362261 | ... AF11: =Feuil1!AB7/1000 -> -4.1845395
A12: MESSAGE2021 | B12: Net Zero 2050 | C12: World | D12: Emissions|CO2 | E12: 14 | F12: Ord | G12: 12 | H12: 12 | I12: 4 | J12: dashed | K12: 0 | L12: limegreen | M12: 0 | N12: Mt CO2/yr | O12: 43.281866 | P12: =Feuil1!L13/1000 -> 42.186671 | Q12: =Feuil1!M13/1000 -> 28.40917 | R12: =Feuil1!N13/1000 -> 19.63951 | S12: =Feuil1!O13/1000 -> 14.101221 | T12: =Feuil1!P13/1000 -> 10.016853 | U12: =Feuil1!Q13/1000 -> 6.4799756 | V12: =Feuil1!R13/1000 -> 3.5385568 | W12: =Feuil1!S13/1000 -> 1.3411439 | X12: =Feuil1!T13/1000 -> -0.0013051182 | Z12: =Feuil1!V13/1000 -> -0.0021356018 | AB12: =Feuil1!X13/1000 -> 0.00052499119 | AD12: =Feuil1!Z13/1000 -> 0.0010013237 | AF12: =Feuil1!AB13/1000 -> 0.0010075875
A13: REMIND2021 | B13: Net Zero 2050 | C13: World | D13: Emissions|CO2 | E13: 14 | F13: Ord | G13: 20 | H13: 20 | I13: 4 | J13: dotted | K13: 0 | L13: limegreen | M13: 0 | N13: Mt CO2/yr | O13: 39.283613 | P13: =Feuil1!L19/1000 -> 39.860861 | Q13: =Feuil1!M19/1000 -> 29.041974 | R13: =Feuil1!N19/1000 -> 19.052596 | S13: =Feuil1!O19/1000 -> 12.582268 | T13: =Feuil1!P19/1000 -> 7.6631894 | U13: =Feuil1!Q19/1000 -> 3.8068609 | V13: =Feuil1!R19/1000 -> 0.940968 | W13: =Feuil1!S19/1000 -> -0.5230373 | X13: =Feuil1!T19/1000 -> -1.1109074 | Z13: =Feuil1!V19/1000 -> -1.2482173 | AB13: =Feuil1!X19/1000 -> -1.013034 | AD13: =Feuil1!Z19/1000 -> -0.8480771 | AF13: =Feuil1!AB19/1000 -> -0.9569566
A14: GCAM2021 | B14: Delayed transition | C14: World | D14: Emissions|CO2 | E14: 15 | F14: Dis | G14: 21 | H14: 21 | I14: 5 | J14: solid | K14: 1 | L14: orange | M14: 0 | N14: Mt CO2/yr | O14: 40.088074 | P14: =Feuil1!L4/1000 -> 41.748377 | Q14: =Feuil1!M4/1000 -> 42.870429 | R14: =Feuil1!N4/1000 -> 43.254566 | S14: =Feuil1!O4/1000 -> 30.460799 | T14: =Feuil1!P4/1000 -> 22.589827 | U14: =Feuil1!Q4/1000 -> 14.16775 | V14: =Feuil1!R4/1000 -> 6.4383737 | W14: =Feuil1!S4/1000 -> 1.3487574 | ... AF14: =Feuil1!AB4/1000 -> -6.8420309
A15: MESSAGE2021 | B15: Delayed transition | C15: World | D15: Emissions|CO2 | E15: 15 | F15: Dis | G15: 20 | H15: 20 | I15: 5 | J15: dashed | K15: 1 | L15: orange | M15: 0 | N15: Mt CO2/yr | O15: 43.281866 | P15: =Feuil1!L10/1000 -> 42.186671 | Q15: =Feuil1!M10/1000 -> 41.961094 | R15: =Feuil1!N10/1000 -> 43.923257 | S15: =Feuil1!O10/1000 -> 29.771637 | T15: =Feuil1!P10/1000 -> 19.815692 | U15: =Feuil1!Q10/1000 -> 12.639482 | V15: =Feuil1!R10/1000 -> 7.6096412 | W15: =Feuil1!S10/1000 -> 3.9392403 | X15: =Feuil1!T10/1000 -> 1.0225163 | Z15: =Feuil1!V10/1000 -> -3.8057208 | AB15: =Feuil1!X10/1000 -> -5.2085828 | AD15: =Feuil1!Z10/1000 -> -5.1671356 | AF15: =Feuil1!AB10/1000 -> -5.0516484
A16: REMIND2021 | B16: Delayed transition | C16: World | D16: Emissions|CO2 | E16: 15 | F16: Dis | G16: 19 | H16: 19 | I16: 5 | J16: dotted | K16: 1 | L16: orange | M16: 0 | N16: Mt CO2/yr | O16: 39.283613 | P16: =Feuil1!L16/1000 -> 39.860861 | Q16: =Feuil1!M16/1000 -> 41.286547 | R16: =Feuil1!N16/1000 -> 42.659504 | S16: =Feuil1!O16/1000 -> 25.706992 | T16: =Feuil1!P16/1000 -> 13.929295 | U16: =Feuil1!Q16/1000 -> 7.5131229 | V16: =Feuil1!R16/1000 -> 3.190721 | W16: =Feuil1!S16/1000 -> 1.1982917 | X16: =Feuil1!T16/1000 -> 0.1424536 | Z16: =Feuil1!V16/1000 -> -1.5689649 | AB16: =Feuil1!X16/1000 -> -2.5940152 | AD16: =Feuil1!Z16/1000 -> -2.8219338 | AF16: =Feuil1!AB16/1000 -> -3.1911078
A17: GCAM2021 | B17: Divergent Net Zero | C17: World | D17: Emissions|CO2 | E17: 16 | F17: Dis | G17: 10 | H17: 10 | I17: 6 | J17: solid | K17: 0 | L17: mediumseagreen | M17: 0 | N17: Mt CO2/yr | O17: 40.088074 | P17: =Feuil1!L5/1000 -> 41.748379 | Q17: =Feuil1!M5/1000 -> 28.707852 | R17: =Feuil1!N5/1000 -> 22.710428 | S17: =Feuil1!O5/1000 -> 15.083193 | T17: =Feuil1!P5/1000 -> 7.8536119 | U17: =Feuil1!Q5/1000 -> 0.57567524 | V17: =Feuil1!R5/1000 -> -6.2167169 | W17: =Feuil1!S5/1000 -> -7.5892129 | ... AF17: =Feuil1!AB5/1000 -> -5.9908504
A18: MESSAGE2021 | B18: Divergent Net Zero | C18: World | D18: Emissions|CO2 | E18: 16 | F18: Dis | G18: 21 | H18: 21 | I18: 6 | J18: dashed | K18: 0 | L18: mediumseagreen | M18: 0 | N18: Mt CO2/yr | O18: 43.281866 | P18: =Feuil1!L11/1000 -> 42.186671 | Q18: =Feuil1!M11/1000 -> 28.093201 | R18: =Feuil1!N11/1000 -> 18.817634 | S18: =Feuil1!O11/1000 -> 12.922295 | T18: =Feuil1!P11/1000 -> 8.7320017 | U18: =Feuil1!Q11/1000 -> 5.3983799 | V18: =Feuil1!R11/1000 -> 2.533375 | W18: =Feuil1!S11/1000 -> 0.67137653 | X18: =Feuil1!T11/1000 -> 2.2737368e-16 | Z18: =Feuil1!V11/1000 -> 6.8212103e-16 | AB18: =Feuil1!X11/1000 -> -9.094947e-16 | AD18: =Feuil1!Z11/1000 -> -7.2759576e-15 | AF18: =Feuil1!AB11/1000 -> 1.3642421e-15
A19: REMIND2021 | B19: Divergent Net Zero | C19: World | D19: Emissions|CO2 | E19: 16 | F19: Dis | G19: 24 | H19: 24 | I19: 6 | J19: dotted | K19: 0 | L19: mediumseagreen | M19: 0 | N19: Mt CO2/yr | O19: 39.283613 | P19: =Feuil1!L17/1000 -> 39.860861 | Q19: =Feuil1!M17/1000 -> 28.93599 | R19: =Feuil1!N17/1000 -> 19.112167 | S19: =Feuil1!O17/1000 -> 12.160942 | T19: =Feuil1!P17/1000 -> 7.2790528 | U19: =Feuil1!Q17/1000 -> 3.9025822 | V19: =Feuil1!R17/1000 -> 1.3729554 | W19: =Feuil1!S17/1000 -> -0.1562887 | X19: =Feuil1!T17/1000 -> -1.2002236 | Z19: =Feuil1!V17/1000 -> -2.1877543 | AB19: =Feuil1!X17/1000 -> -2.5548512 | AD19: =Feuil1!Z17/1000 -> -2.9910599 | AF19: =Feuil1!AB17/1000 -> -3.6280647

Sheet CPrice
A1: Model | B1: Scenario | C1: Code | D1: Region | E1: Variable | F1: Unit | G1: 2015 | H1: 2020 | I1: 2025 | J1: 2030 | K1: 2035 | L1: 2040 | M1: 2045 | N1: 2050 | O1: 2055 | P1: 2060 | Q1: 2065 | R1: 2070 | S1: 2075 | T1: 2080 | U1: 2085 | V1: 2090 | W1: 2095 | X1: 2100
A2: GCAM | B2: Current Policies | C2: 1 | D2: World | E2: Emissions|CO2 | F2: dashdot | G2: 0 | H2: 0 | I2: 0 | J2: 0 | K2: 0 | L2: 0 | M2: 0 | N2: 0 | O2: 0 | P2: 0 | Q2: 0 | R2: 0 | S2: 0 | T2: 0 | U2: 0 | V2: 0 | W2: 0 | X2: 0
A3: MESSAGEix-GLOBIOM 1.1 | B3: Current Policies | C3: 1 | D3: World | E3: Price|Carbon | F3: US$2010/t CO2 | G3: 0 | H3: 0.57609089 | I3: 0.70024571 | J3: 0.30522656 | K3: 0.44600253 | L3: 0.55389339 | M3: 0.66178425 | N3: 0.76967511 | O3: 0.87756597 | P3: 0.98545683 | R3: 1.2012386 | T3: 1.4170203 | V3: 1.632802 | X3: 1.8485837
A4: REMIND-MAgPIE 2.1-4.2 | B4: Current Policies | C4: 1 | D4: World | E4: Price|Carbon | F4: US$2010/t CO2 | G4: 0 | H4: 0.35463526 | I4: 0.29538647 | J4: 0.29566798 | K4: 0.31271007 | L4: 0.33914463 | M4: 0.37334937 | N4: 0.4220087 | O4: 0.48557311 | P4: 0.56284924 | R4: 0.74730435 | T4: 0.98372996 | V4: 1.2861919 | X4: 1.669003
A5: GCAM5.3_NGFS | B5: Nationally Determined Contributions (NDCs) | C5: 2 | D5: World | E5: Price|Carbon | F5: US$2010/t CO2 | G5: 0 | H5: 0 | I5: 3.5775145 | J5: 9.5013159 | K5: 9.8786888 | L5: 11.365805 | M5: 14.757751 | N5: 18.655263 | O5: 21.9482 | P5: 26.281424 | Q5: 31.406456 | R5: 36.182052 | S5: 41.74612 | T5: 47.895463 | U5: 52.401453 | V5: 56.689195 | W5: 61.852742 | X5: 69.21763
A6: MESSAGEix-GLOBIOM 1.1 | B6: Nationally Determined Contributions (NDCs) | C6: 2 | D6: World | E6: Price|Carbon | F6: US$2010/t CO2 | G6: 0 | H6: 0.57609089 | I6: 3.0447975 | J6: 13.266184 | K6: 14.592449 | L6: 14.489415 | M6: 14.38638 | N6: 14.283346 | O6: 14.180312 | P6: 14.077278 | R6: 13.871209 | T6: 13.665141 | V6: 13.459073 | X6: 13.253004
A7: REMIND-MAgPIE 2.1-4.2 | B7: Nationally Determined Contributions (NDCs) | C7: 2 | D7: World | E7: Price|Carbon | F7: US$2010/t CO2 | G7: 0 | H7: 0.35463526 | I7: 1.0126441 | J7: 1.1835517 | K7: 1.7467035 | L7: 2.4757981 | M7: 3.2453656 | N7: 4.0420555 | O7: 4.8865221 | P7: 5.7392122 | R7: 7.422895 | T7: 8.9618096 | V7: 10.409476 | X7: 11.964361
A8: GCAM5.3_NGFS | B8: Below 2°C | C8: 3 | D8: World | E8: Price|Carbon | F8: US$2010/t CO2 | G8: 0 | H8: 0 | I8: 4.9242517 | J8: 9.1773763 | K8: 12.948433 | L8: 16.00323 | M8: 21.882968 | N8: 31.543437 | O8: 46.340333 | P8: 69.383215 | Q8: 110.51597 | R8: 101.37623 | S8: 93.706626 | T8: 90.332089 | U8: 89.20447 | V8: 89.718233 | W8: 91.383663 | X8: 101.15247
A9: MESSAGEix-GLOBIOM 1.1 | B9: Below 2°C | C9: 3 | D9: World | E9: Price|Carbon | F9: US$2010/t CO2 | G9: 0 | H9: 0.57609089 | I9: 4.9750873 | J9: 6.4555841 | K9: 7.5020532 | L9: 10.735508 | M9: 13.103748 | N9: 15.690894 | O9: 21.888357 | P9: 28.763712 | R9: 39.114096 | T9: 33.186259 | V9: 27.414669 | X9: 24.046054
A10: REMIND-MAgPIE 2.1-4.2 | B10: Below 2°C | C10: 3 | D10: World | E10: Price|Carbon | F10: US$2010/t CO2 | G10: 0 | H10: 0.35463526 | I10: 5.1044581 | J10: 6.8707885 | K10: 9.2560784 | L10: 12.595014 | M10: 17.127734 | N10: 22.951867 | O10: 25.820965 | P10: 28.690305 | R10: 34.428427 | T10: 40.167936 | V10: 45.90599 | X10: 49.849166
A11: GCAM5.3_NGFS | B11: Net Zero 2050 | C11: 4 | D11: World | E11: Price|Carbon | F11: US$2010/t CO2 | G11: 0 | H11: 0 | I11: 7.248753 | J11: 11.496856 | K11: 16.345415 | L11: 20.742376 | M11: 31.765495 | N11: 66.731278 | O11: 90.471704 | P11: 101.6785 | Q11: 107.80775 | R11: 132.36282 | S11: 172.81135 | T11: 231.66071 | U11: 240.97709 | V11: 266.52688 | W11: 294.18236 | X11: 375.74695
A12: MESSAGEix-GLOBIOM 1.1 | B12: Net Zero 2050 | C12: 4 | D12: World | E12: Price|Carbon | F12: US$2010/t CO2 | G12: 0 | H12: 0.57609089 | I12: 17.269103 | J12: 23.470317 | K12: 32.675975 | L12: 40.066055 | M12: 49.461718 | N12: 57.710995 | O12: 92.431376 | P12: 71.54103 | R12: 30.324775 | T12: 24.989254 | V12: 30.498837 | X12: 25.611556
A13: REMIND-MAgPIE 2.1-4.2 | B13: Net Zero 2050 | C13: 4 | D13: World | E13: Price|Carbon | F13: US$2010/t CO2 | G13: 0 | H13: 0.35463526 | I13: 16.062265 | J13: 21.846901 | K13: 31.824893 | L13: 44.06292 | M13: 60.403291 | N13: 79.843918 | O13: 78.187091 | P13: 76.511135 | R13: 72.789291 | T13: 69.824212 | V13: 67.364154 | X13: 65.011456
A14: GCAM5.3_NGFS | B14: Delayed transition | C14: 5 | D14: World | E14: Price|Carbon | F14: US$2010/t CO2 | G14: 0 | H14: 0 | I14: 0 | J14: 0 | K14: 16.05689 | L14: 22.422262 | M14: 39.027063 | N14: 83.559419 | O14: 107.87716 | P14: 185.59349 | Q14: 276.7142 | R14: 367.83516 | S14: 458.95575 | T14: 550.076 | U14: 641.19885 | V14: 732.31838 | W14: 823.44028 | X14: 914.55981
A15: MESSAGEix-GLOBIOM 1.1 | B15: Delayed transition | C15: 5 | D15: World | E15: Price|Carbon | F15: US$2010/t CO2 | G15: 0 | H15: 0.57609089 | I15: 0.70024571 | J15: 0.30522656 | K15: 42.06983 | L15: 76.380706 | M15: 68.923675 | N15: 109.83741 | O15: 192.12908 | P15: 150.71222 | R15: 256.70158 | T15: 60.748151 | V15: 55.529495 | X15: 31.699339
A16: REMIND-MAgPIE 2.1-4.2 | B16: Delayed transition | C16: 5 | D16: World | E16: Price|Carbon | F16: US$2010/t CO2 | G16: 0 | H16: 0.35463526 | I16: 0.29538647 | J16: 0.29566798 | K16: 27.520168 | L16: 39.424592 | M16: 54.631669 | N16: 73.816567 | O16: 81.185749 | P16: 89.226137 | R16: 100.77993 | T16: 112.80688 | V16: 124.63017 | X16: 136.79247
A17: GCAM5.3_NGFS | B17: Divergent Net Zero | C17: 6 | D17: World | E17: Price|Carbon | F17: US$2010/t CO2 | G17: 0 | H17: 0 | I17: 24.246226 | J17: 31.296976 | K17: 41.928607 | L17: 50.065339 | M17: 87.967204 | N17: 195.43163 | O17: 212.64863 | P17: 212.92839 | Q17: 236.71028 | R17: 247.22401 | S17: 254.87207 | T17: 308.08102 | U17: 301.40159 | V17: 286.98319 | W17: 267.79592 | X17: 267.34703
A18: MESSAGEix-GLOBIOM 1.1 | B18: Divergent Net Zero | C18: 6 | D18: World | E18: Price|Carbon | F18: US$2010/t CO2 | G18: 0 | H18: 0.57609089 | I18: 19.860683 | J18: 26.751514 | K18: 37.289678 | L18: 43.910379 | M18: 57.531175 | N18: 84.218975 | O18: 130.97124 | P18: 158.57525 | R18: 60.051197 | T18: 50.904454 | V18: 60.120595 | X18: 52.816567
A19: REMIND-MAgPIE 2.1-4.2 | B19: Divergent Net Zero | C19: 6 | D19: World | E19: Price|Carbon | F19: US$2010/t CO2 | G19: 0 | H19: 0.35463526 | I19: 22.06321 | J19: 33.044016 | K19: 46.633223 | L19: 60.66797 | M19: 76.855802 | N19: 92.953542 | O19: 95.741703 | P19: 94.217276 | R19: 98.380024 | T19: 102.02875 | V19: 107.04441 | X19: 109.849

Sheet Feuil1
A1: Model | B1: Scenario | C1: Region | D1: Variable | E1: Unit | F1: 1990 | G1: 1995 | H1: 2000 | I1: 2005 | J1: 2010 | K1: 2015 | L1: 2020 | M1: 2025 | N1: 2030 | O1: 2035 | P1: 2040 | Q1: 2045 | R1: 2050 | S1: 2055 | T1: 2060 | U1: 2065 | V1: 2070 | W1: 2075 | X1: 2080 | Y1: 2085 | Z1: 2090 | AA1: 2095 | AB1: 2100
A2: GCAM5.3_NGFS | B2: Below 2°C | C2: World | D2: Emissions|CO2 | E2: Mt CO2/yr | I2: 30330.069 | J2: 34654.239 | K2: 40088.074 | L2: 41741.753 | M2: 37793.758 | N2: 32406.955 | O2: 25829.202 | P2: 18922.584 | Q2: 12067.988 | R2: 8278.4755 | S2: 4645.6852 | T2: 1076.8034 | U2: -2404.6804 | V2: -2832.5262 | W2: -2910.6825 | X2: -2711.4141 | Y2: -2469.7761 | Z2: -2180.1616 | AA2: -1864.6336 | AB2: -1247.6435
A3: GCAM5.3_NGFS | B3: Nationally Determined Contributions (NDCs) | C3: World | D3: Emissions|CO2 | E3: Mt CO2/yr | I3: 30330.069 | J3: 34654.239 | K3: 40088.076 | L3: 42010.319 | M3: 41518.275 | N3: 39157.197 | O3: 36726.453 | P3: 34248.834 | Q3: 31693.521 | R3: 28901.923 | S3: 27006.103 | T3: 24433.936 | U3: 21956.864 | V3: 19003.339 | W3: 18494.584 | X3: 18505.716 | Y3: 17889.876 | Z3: 17419.859 | AA3: 16434.663 | AB3: 15817.734
A4: GCAM5.3_NGFS | B4: Delayed transition | C4: World | D4: Emissions|CO2 | E4: Mt CO2/yr | I4: 30330.069 | J4: 34654.24 | K4: 40088.075 | L4: 41748.377 | M4: 42870.429 | N4: 43254.566 | O4: 30460.799 | P4: 22589.827 | Q4: 14167.75 | R4: 6438.3737 | S4: 1348.7574 | T4: -4040.5261 | U4: -6862.144 | V4: -8725.1107 | W4: -10265.992 | X4: -11696.995 | Y4: -13100.152 | Z4: -11003.629 | AA4: -8984.7075 | AB4: -6842.0309
A5: GCAM5.3_NGFS | B5: Divergent Net Zero | C5: World | D5: Emissions|CO2 | E5: Mt CO2/yr | I5: 30330.069 | J5: 34654.24 | K5: 40088.075 | L5: 41748.379 | M5: 28707.852 | N5: 22710.428 | O5: 15083.193 | P5: 7853.6119 | Q5: 575.67524 | R5: -6216.7169 | S5: -7589.2129 | T5: -7980.0165 | U5: -8197.6939 | V5: -8101.2674 | W5: -7886.0808 | X5: -7769.4107 | Y5: -7503.4404 | Z5: -7158.0485 | AA5: -6821.0426 | AB5: -5990.8504
A6: GCAM5.3_NGFS | B6: Current Policies | C6: World | D6: Emissions|CO2 | E6: Mt CO2/yr | I6: 30330.069 | J6: 34654.239 | K6: 40088.073 | L6: 41748.377 | M6: 42870.429 | N6: 43254.566 | O6: 44092.383 | P6: 43654.93 | Q6: 43423.747 | R6: 42993.373 | S6: 44085.214 | T6: 44816.835 | U6: 45735.583 | V6: 46162.812 | W6: 46702.604 | X6: 47606.184 | Y6: 47749.916 | Z6: 47904.237 | AA6: 48510.541 | AB6: 47172.663
A7: GCAM5.3_NGFS | B7: Net Zero 2050 | C7: World | D7: Emissions|CO2 | E7: Mt CO2/yr | I7: 30330.069 | J7: 34654.239 | K7: 40088.073 | L7: 41747.491 | M7: 34422.147 | N7: 27631.832 | O7: 18783.933 | P7: 10015.229 | Q7: 4747.7467 | R7: -311.04255 | S7: -3236.2261 | T7: -4751.9839 | U7: -5309.015 | V7: -5702.4059 | W7: -5790.9837 | X7: -5745.1703 | Y7: -5424.8996 | Z7: -5135.3793 | AA7: -4802.456 | AB7: -4184.5395
A8: MESSAGEix-GLOBIOM 1.1 | B8: Below 2°C | C8: World | D8: Emissions|CO2 | E8: Mt CO2/yr | F8: 29417.026 | G8: 30116.684 | H8: 32281.145 | I8: 36621.789 | J8: 39410.655 | K8: 43281.866 | L8: 42186.671 | M8: 33099.994 | N8: 28346.452 | O8: 25099.181 | P8: 21665.792 | Q8: 17637.859 | R8: 13326.326 | S8: 9831.9234 | T8: 7120.7952 | V8: 2438.2968 | X8: 0.0019765012 | Z8: -0.0027184535 | AB8: 2.6274698e-05
A9: MESSAGEix-GLOBIOM 1.1 | B9: Nationally Determined Contributions (NDCs) | C9: World | D9: Emissions|CO2 | E9: Mt CO2/yr | F9: 29417.026 | G9: 30116.684 | H9: 32281.145 | I9: 36621.789 | J9: 39410.655 | K9: 43281.866 | L9: 42186.671 | M9: 39683.069 | N9: 39561.825 | O9: 39291.989 | P9: 36993.37 | Q9: 35315.429 | R9: 33195.025 | S9: 31281.624 | T9: 29501.521 | V9: 27898.152 | X9: 26807.177 | Z9: 22933.888 | AB9: 19522.563
A10: MESSAGEix-GLOBIOM 1.1 | B10: Delayed transition | C10: World | D10: Emissions|CO2 | E10: Mt CO2/yr | F10: 29417.026 | G10: 30116.684 | H10: 32281.145 | I10: 36621.789 | J10: 39410.655 | K10: 43281.866 | L10: 42186.671 | M10: 41961.094 | N10: 43923.257 | O10: 29771.637 | P10: 19815.692 | Q10: 12639.482 | R10: 7609.6412 | S10: 3939.2403 | T10: 1022.5163 | V10: -3805.7208 | X10: -5208.5828 | Z10: -5167.1356 | AB10: -5051.6484
A11: MESSAGEix-GLOBIOM 1.1 | B11: Divergent Net Zero | C11: World | D11: Emissions|CO2 | E11: Mt CO2/yr | F11: 29417.026 | G11: 30116.684 | H11: 32281.145 | I11: 36621.789 | J11: 39410.655 | K11: 43281.866 | L11: 42186.671 | M11: 28093.201 | N11: 18817.634 | O11: 12922.295 | P11: 8732.0017 | Q11: 5398.3799 | R11: 2533.375 | S11: 671.37653 | T11: 2.2737368e-13 | V11: 6.8212103e-13 | X11: -9.094947e-13 | Z11: -7.2759576e-12 | AB11: 1.3642421e-12
A12: MESSAGEix-GLOBIOM 1.1 | B12: Current Policies | C12: World | D12: Emissions|CO2 | E12: Mt CO2/yr | F12: 29417.026 | G12: 30116.684 | H12: 32281.145 | I12: 36621.789 | J12: 39410.655 | K12: 43281.866 | L12: 42186.671 | M12: 41961.094 | N12: 43923.257 | O12: 45475.716 | P12: 46165.963 | Q12: 47455.607 | R12: 48830.181 | S12: 50403.311 | T12: 50760.493 | V12: 53578.041 | X12: 60794.01 | Z12: 65799.357 | AB12: 68642.039
A13: MESSAGEix-GLOBIOM 1.1 | B13: Net Zero 2050 | C13: World | D13: Emissions|CO2 | E13: Mt CO2/yr | F13: 29417.026 | G13: 30116.684 | H13: 32281.145 | I13: 36621.789 | J13: 39410.655 | K13: 43281.866 | L13: 42186.671 | M13: 28409.17 | N13: 19639.51 | O13: 14101.221 | P13: 10016.853 | Q13: 6479.9756 | R13: 3538.5568 | S13: 1341.1439 | T13: -1.3051182 | V13: -2.1356018 | X13: 0.52499119 | Z13: 1.0013237 | AB13: 1.0075875
A14: REMIND-MAgPIE 2.1-4.2 | B14: Below 2°C | C14: World | D14: Emissions|CO2 | E14: Mt CO2/yr | I14: 33464.459 | J14: 37155.096 | K14: 39283.613 | L14: 39860.861 | M14: 32974.091 | N14: 28023.844 | O14: 22449.621 | P14: 16923.235 | Q14: 12756.09 | R14: 9526.017 | S14: 6983.6848 | T14: 5109.653 | V14: 2655.1331 | X14: 1372.0141 | Z14: 673.9603 | AB14: 120.9158
A15: REMIND-MAgPIE 2.1-4.2 | B15: Nationally Determined Contributions (NDCs) | C15: World | D15: Emissions|CO2 | E15: Mt CO2/yr | I15: 33464.459 | J15: 37155.096 | K15: 39283.613 | L15: 39860.861 | M15: 40871.447 | N15: 40720.627 | O15: 38904.909 | P15: 34834.107 | Q15: 30650.156 | R15: 27857.62 | S15: 25455.274 | T15: 23566.903 | V15: 18119.073 | X15: 14001.371 | Z15: 10084.444 | AB15: 7721.1935
A16: REMIND-MAgPIE 2.1-4.2 | B16: Delayed transition | C16: World | D16: Emissions|CO2 | E16: Mt CO2/yr | I16: 33464.459 | J16: 37155.096 | K16: 39283.613 | L16: 39860.861 | M16: 41286.547 | N16: 42659.504 | O16: 25706.992 | P16: 13929.295 | Q16: 7513.1229 | R16: 3190.721 | S16: 1198.2917 | T16: 142.4536 | V16: -1568.9649 | X16: -2594.0152 | Z16: -2821.9338 | AB16: -3191.1078
A17: REMIND-MAgPIE 2.1-4.2 | B17: Divergent Net Zero | C17: World | D17: Emissions|CO2 | E17: Mt CO2/yr | I17: 33464.459 | J17: 37155.096 | K17: 39283.613 | L17: 39860.861 | M17: 28935.99 | N17: 19112.167 | O17: 12160.942 | P17: 7279.0528 | Q17: 3902.5822 | R17: 1372.9554 | S17: -156.2887 | T17: -1200.2236 | V17: -2187.7543 | X17: -2554.8512 | Z17: -2991.0599 | AB17: -3628.0647
A18: REMIND-MAgPIE 2.1-4.2 | B18: Current Policies | C18: World | D18: Emissions|CO2 | E18: Mt CO2/yr | I18: 33464.459 | J18: 37155.096 | K18: 39283.613 | L18: 39860.861 | M18: 41286.547 | N18: 42659.504 | O18: 43132.513 | P18: 42609.539 | Q18: 42184.799 | R18: 41927.365 | S18: 41317.866 | T18: 40758.66 | V18: 39453.863 | X18: 38015.772 | Z18: 34313.074 | AB18: 30117.557
A19: REMIND-MAgPIE 2.1-4.2 | B19: Net Zero 2050 | C19: World | D19: Emissions|CO2 | E19: Mt CO2/yr | I19: 33464.459 | J19: 37155.096 | K19: 39283.613 | L19: 39860.861 | M19: 29041.974 | N19: 19052.596 | O19: 12582.268 | P19: 7663.1894 | Q19: 3806.8609 | R19: 940.968 | S19: -523.0373 | T19: -1110.9074 | V19: -1248.2173 | X19: -1013.034 | Z19: -848.0771 | AB19: -956.9566
A20: GCAM5.3_NGFS | B20: Below 2°C | C20: World | D20: Price|Carbon | E20: US$2010/t CO2 | I20: 0 | J20: 0 | K20: 0 | L20: 0 | M20: 41.48817 | N20: 77.32191 | O20: 109.0941 | P20: 134.8316 | Q20: 184.37 | R20: 265.7621 | S20: 390.43 | T20: 584.5726 | U20: 931.1273 | V20: 854.1225 | W20: 789.504 | X20: 761.0726 | Y20: 751.5721 | Z20: 755.9007 | AA20: 769.9324 | AB20: 852.2373
A21: GCAM5.3_NGFS | B21: Nationally Determined Contributions (NDCs) | C21: World | D21: Price|Carbon | E21: US$2010/t CO2 | I21: 0 | J21: 0 | K21: 0 | L21: 0 | M21: 30.14154 | N21: 80.05119 | O21: 83.23066 | P21: 95.76002 | Q21: 124.3381 | R21: 157.1757 | S21: 184.9196 | T21: 221.4282 | U21: 264.608 | V21: 304.8437 | W21: 351.7225 | X21: 403.5324 | Y21: 441.4966 | Z21: 477.622 | AA21: 521.1263 | AB21: 583.1775
A22: GCAM5.3_NGFS | B22: Delayed transition | C22: World | D22: Price|Carbon | E22: US$2010/t CO2 | I22: 0 | J22: 0 | K22: 0 | L22: 0 | M22: 0 | N22: 0 | O22: 135.2837 | P22: 188.9137 | Q22: 328.8137 | R22: 704.011 | S22: 908.8946 | T22: 1563.676 | U22: 2331.393 | V22: 3099.112 | W22: 3866.828 | X22: 4634.541 | Y22: 5402.276 | Z22: 6169.983 | AA22: 6937.71 | AB22: 7705.417
A23: GCAM5.3_NGFS | B23: Divergent Net Zero | C23: World | D23: Price|Carbon | E23: US$2010/t CO2 | I23: 0 | J23: 0 | K23: 0 | L23: 0 | M23: 204.2811 | N23: 263.6856 | O23: 353.26 | P23: 421.8142 | Q23: 741.1478 | R23: 1646.565 | S23: 1791.623 | T23: 1793.98 | U23: 1994.349 | V23: 2082.93 | W23: 2147.367 | X23: 2595.667 | Y23: 2539.391 | Z23: 2417.912 | AA23: 2256.254 | AB23: 2252.472
A24: GCAM5.3_NGFS | B24: Net Zero 2050 | C24: World | D24: Price|Carbon | E24: US$2010/t CO2 | I24: 0 | J24: 0 | K24: 0 | L24: 0 | M24: 61.07273 | N24: 96.86416 | O24: 137.7146 | P24: 174.7602 | Q24: 267.633 | R24: 562.2293 | S24: 762.2489 | T24: 856.6692 | U24: 908.3098 | V24: 1115.193 | W24: 1455.983 | X24: 1951.805 | Y24: 2030.298 | Z24: 2245.562 | AA24: 2478.567 | AB24: 3165.771
A25: MESSAGEix-GLOBIOM 1.1 | B25: Below 2°C | C25: World | D25: Price|Carbon | E25: US$2010/t CO2 | F25: 0 | G25: 0 | H25: 0 | I25: 0 | J25: 0 | K25: 0 | L25: 4.8537236 | M25: 41.916473 | N25: 54.390065 | O25: 63.206854 | P25: 90.449601 | Q25: 110.40267 | R25: 132.20008 | S25: 184.4154 | T25: 242.34215 | V25: 329.54697 | X25: 279.60333 | Z25: 230.9761 | AB25: 202.59459
A26: MESSAGEix-GLOBIOM 1.1 | B26: Nationally Determined Contributions (NDCs) | C26: World | D26: Price|Carbon | E26: US$2010/t CO2 | F26: 0 | G26: 0 | H26: 0 | I26: 0 | J26: 0 | K26: 0 | L26: 4.8537236 | M26: 25.653253 | N26: 111.77124 | O26: 122.94538 | P26: 122.07729 | Q26: 121.2092 | R26: 120.34111 | S26: 119.47301 | T26: 118.60492 | V26: 116.86874 | X26: 115.13256 | Z26: 113.39637 | AB26: 111.66019
A27: MESSAGEix-GLOBIOM 1.1 | B27: Delayed transition | C27: World | D27: Price|Carbon | E27: US$2010/t CO2 | F27: 0 | G27: 0 | H27: 0 | I27: 0 | J27: 0 | K27: 0 | L27: 4.8537236 | M27: 5.899762 | N27: 2.5716174 | O27: 354.44985 | P27: 643.52838 | Q27: 580.70085 | R27: 925.41031 | S27: 1618.7401 | T27: 1269.7918 | V27: 2162.7812 | X27: 511.81982 | Z27: 467.85121 | AB27: 267.07561
A28: MESSAGEix-GLOBIOM 1.1 | B28: Divergent Net Zero | C28: World | D28: Price|Carbon | E28: US$2010/t CO2 | F28: 0 | G28: 0 | H28: 0 | I28: 0 | J28: 0 | K28: 0 | L28: 4.8537236 | M28: 167.3317 | N28: 225.38883 | O28: 314.17575 | P28: 369.95697 | Q28: 484.71592 | R28: 709.56794 | S28: 1103.4686 | T28: 1336.0399 | V28: 505.94779 | X28: 428.88398 | Z28: 506.53249 | AB28: 444.99405
A29: MESSAGEix-GLOBIOM 1.1 | B29: Current Policies | C29: World | D29: Price|Carbon | E29: US$2010/t CO2 | F29: 0 | G29: 0 | H29: 0 | I29: 0 | J29: 0 | K29: 0 | L29: 4.8537236 | M29: 5.899762 | N29: 2.5716174 | O29: 3.7576935 | P29: 4.6667036 | Q29: 5.5757137 | R29: 6.4847237 | S29: 7.3937338 | T29: 8.3027439 | V29: 10.120764 | X29: 11.938784 | Z29: 13.756804 | AB29: 15.574824
A30: MESSAGEix-GLOBIOM 1.1 | B30: Net Zero 2050 | C30: World | D30: Price|Carbon | E30: US$2010/t CO2 | F30: 0 | G30: 0 | H30: 0 | I30: 0 | J30: 0 | K30: 0 | L30: 4.8537236 | M30: 145.49693 | N30: 197.74385 | O30: 275.30405 | P30: 337.56749 | Q30: 416.72853 | R30: 486.23095 | S30: 778.75967 | T30: 602.75278 | V30: 255.49454 | X30: 210.54131 | Z30: 256.96106 | AB30: 215.78438
A31: REMIND-MAgPIE 2.1-4.2 | B31: Below 2°C | C31: World | D31: Price|Carbon | E31: US$2010/t CO2 | I31: 0 | J31: 2.0929169 | K31: 1.705778 | L31: 2.9878992 | M31: 43.006458 | N31: 57.888276 | O31: 77.984997 | P31: 106.11644 | Q31: 144.30585 | R31: 193.37577 | S31: 217.54871 | T31: 241.72368 | V31: 290.06893 | X31: 338.42587 | Z31: 386.77055 | AB31: 419.99288
A32: REMIND-MAgPIE 2.1-4.2 | B32: Nationally Determined Contributions (NDCs) | C32: World | D32: Price|Carbon | E32: US$2010/t CO2 | I32: 0 | J32: 2.0929169 | K32: 1.705778 | L32: 2.9878992 | M32: 8.5318041 | N32: 9.9717474 | O32: 14.716456 | P32: 20.859278 | Q32: 27.343094 | R32: 34.055425 | S32: 41.170288 | T32: 48.354435 | V32: 62.539924 | X32: 75.505701 | Z32: 87.702689 | AB32: 100.80302
A33: REMIND-MAgPIE 2.1-4.2 | B33: Delayed transition | C33: World | D33: Price|Carbon | E33: US$2010/t CO2 | I33: 0 | J33: 2.0929169 | K33: 1.705778 | L33: 2.9878992 | M33: 2.4887119 | N33: 2.4910837 | O33: 231.86496 | P33: 332.16299 | Q33: 460.28678 | R33: 621.9248 | S33: 684.01218 | T33: 751.75465 | V33: 849.09851 | X33: 950.4289 | Z33: 1050.0433 | AB33: 1152.5141
A34: REMIND-MAgPIE 2.1-4.2 | B34: Divergent Net Zero | C34: World | D34: Price|Carbon | E34: US$2010/t CO2 | I34: 0 | J34: 2.0929169 | K34: 1.705778 | L34: 2.9878992 | M34: 185.88859 | N34: 278.40489 | O34: 392.89768 | P34: 511.14427 | Q34: 647.5312 | R34: 783.15906 | S34: 806.65009 | T34: 793.80637 | V34: 828.87866 | X34: 859.62014 | Z34: 901.87851 | AB34: 925.50794
A35: REMIND-MAgPIE 2.1-4.2 | B35: Current Policies | C35: World | D35: Price|Carbon | E35: US$2010/t CO2 | I35: 0 | J35: 2.0929169 | K35: 1.705778 | L35: 2.9878992 | M35: 2.4887119 | N35: 2.4910837 | O35: 2.634668 | P35: 2.8573864 | Q35: 3.1455708 | R35: 3.5555389 | S35: 4.0910865 | T35: 4.7421591 | V35: 6.296244 | X35: 8.2881945 | Z35: 10.836519 | AB35: 14.061807
A36: REMIND-MAgPIE 2.1-4.2 | B36: Net Zero 2050 | C36: World | D36: Price|Carbon | E36: US$2010/t CO2 | I36: 0 | J36: 2.0929169 | K36: 1.705778 | L36: 2.9878992 | M36: 135.32898 | N36: 184.06613 | O36: 268.13345 | P36: 371.24218 | Q36: 508.91428 | R36: 672.70689 | S36: 658.74767 | T36: 644.62728 | V36: 613.26972 | X36: 588.28812 | Z36: 567.56145 | AB36: 547.73934
L38: =L20*1.186905016/10 -> 0 | M38: =M20*1.186905016/10 -> 4.9242517 | N38: =N20*1.186905016/10 -> 9.1773763 | O38: =O20*1.186905016/10 -> 12.948433 | P38: =P20*1.186905016/10 -> 16.00323 | Q38: =Q20*1.186905016/10 -> 21.882968 | R38: =R20*1.186905016/10 -> 31.543437 | S38: =S20*1.186905016/10 -> 46.340333 | ... AB38: =AB20*1.186905016/10 -> 101.15247
L39: =L21*1.186905016/10 -> 0 | M39: =M21*1.186905016/10 -> 3.5775145 | N39: =N21*1.186905016/10 -> 9.5013159 | O39: =O21*1.186905016/10 -> 9.8786888 | P39: =P21*1.186905016/10 -> 11.365805 | Q39: =Q21*1.186905016/10 -> 14.757751 | R39: =R21*1.186905016/10 -> 18.655263 | S39: =S21*1.186905016/10 -> 21.9482 | ... AB39: =AB21*1.186905016/10 -> 69.21763
L40: =L22*1.186905016/10 -> 0 | M40: =M22*1.186905016/10 -> 0 | N40: =N22*1.186905016/10 -> 0 | O40: =O22*1.186905016/10 -> 16.05689 | P40: =P22*1.186905016/10 -> 22.422262 | Q40: =Q22*1.186905016/10 -> 39.027063 | R40: =R22*1.186905016/10 -> 83.559419 | S40: =S22*1.186905016/10 -> 107.87716 | ... AB40: =AB22*1.186905016/10 -> 914.55981
L41: =L23*1.186905016/10 -> 0 | M41: =M23*1.186905016/10 -> 24.246226 | N41: =N23*1.186905016/10 -> 31.296976 | O41: =O23*1.186905016/10 -> 41.928607 | P41: =P23*1.186905016/10 -> 50.065339 | Q41: =Q23*1.186905016/10 -> 87.967204 | R41: =R23*1.186905016/10 -> 195.43163 | S41: =S23*1.186905016/10 -> 212.64863 | ... AB41: =AB23*1.186905016/10 -> 267.34703
...

Sheet README
A1: © NGFS Scenario Explorer https://data.ene.iiasa.ac.at/ngfs
A2: NGFS Scenario Explorer and Data hosted by IIASA
